Workbook

Sheet Start Set
A1: Title | B1: Authors | C1: Year | D1: Venue
A2: Non-Intrusive Distributed Tracing of Wireless IoT Devices with the FlockLab 2 Testbed | B2: Trub, Roman and Da Forno, Reto and Daschinger, Lukas and Biri, Andreas and Beutel, Jan and Thiele, Lothar | C2: 2021 | D2: ACM Transactions on Internet of Things, Volume 3, Issue 1
A3: Distributed Graph Routing and Scheduling for Industrial Wireless Sensor-Actuator Networks | B3: Shi, Junyang and Sha, Mo and Yang, Zhicheng | C3: 2019 | D3: IEEE/ACM Transactions on Networking (TON), Volume 27, Issue 4
A4: Ensuring End-to-End Dependability Requirements in Cloud-based Bluetooth Low Energy Applications | B4: Sp\"{o}rk, Michael and Schu\ss{}, Markus and Boano, Carlo Alberto and R\"{o}mer, Kay | C4: 2021 | D4: Proceedings of the 2021 International Conference on Embedded Wireless Systems and Networks
A5: Unobtrusive, Accurate, and Live Measurements of Network Latency and Reliability for Time-Critical Internet of Things | B5: Bhimavarapu K. and Pang Z. and Dobrijevic O. and Wiatr P. | C5: 2022 | D5: IEEE Internet of Things Magazine
A6: On the Performance of Commodity Hardware for Low Latency and Low Jitter Packet Processing | B6: Stylianopoulos, Charalampos and Almgren, Magnus and Landsiedel, Olaf and Papatriantafilou, Marina and Neish, Trevor and Gillander, Linus and Johansson, Bengt and Bonnier, Staffan | C6: 2020 | D6: DEBS 2020 - Proceedings of the 14th ACM International Conference on Distributed and Event-Based Systems
A7: Fog network task scheduling for IoT applications | B7: Zhang, Chongchong and Shen, Fei and Jin, Jiong and Yang, Yang | C7: 2020 | D7: OpenAccess Series in Informatics
A8: A software architecture for the industrial internet of things - a conceptual model | B8: Ungurean, Ioan and Gaitan, Nicoleta Cristina | C8: 2020 | D8: Sensors (Switzerland)
A9: Analysis of joint scheduling and power control for predictable URLLC in industrial wireless networks | B9: Wang, Ling and Zhang, Hongwei | C9: 2019 | D9: Proceedings - IEEE International Conference on Industrial Internet Cloud, ICII 2019
A10: PrioMQTT: A prioritized version of the MQTT protocol | B10: Patti, Gaetano and Leonardi, Luca and Testa, Giuseppe and Lo Bello, Lucia | C10: 2024 | D10: Computer Communications
A11: RT-BLE: Real-time Multi-Connection Scheduling for Bluetooth Low Energy | B11: Li, Yeming and Lv, Jiamei and Li, Borui and Dong, Wei | C11: 2023 | D11: Proceedings - IEEE INFOCOM
A12: Towards Multi-channel GTS Allocation in Visible Light Communication | B12: Kurunathan, Harrison and Samano-Robles, Ramiro and Gaitan, Miguel Gutierrez and Indhumathi, R. and Tovar, Eduardo | C12: 2023 | D12: 2023 South American Conference on Visible Light Communications, SACVLC 2023
A13: Transmission Early-Stopping Scheme for Anti-Jamming Over Delay-Sensitive IoT Applications | B13: Halloush, RD | C13: 2019 | D13: IEEE INTERNET OF THINGS JOURNAL
... A39: End-to-end response time analysis for RT-MQTT: Trajectory approach versus holistic approach | B39: E. Shahri, P. Pedreiras, L. Almeida | C39: 2023 | D39: 19th International Conference on Factory Communication Systems, WFCS

Sheet Iteration 1 - Forward
A1: Title | B1: Authors | C1: Year | D1: Venue | E1: D | F1: DS | G1: EC1 | H1: EC2-4 | I1: EC5 | J1: EC6 | K1: IC1
A2: Analysis of simulators for designing network architecture in Wireless Sensor Network applications. | B2: MG Periwal, J Deere | C2: 2025 | D2: saeindia.org | E2: =--(ROW(A2)<>MATCH(A2,$A:$A,0)) -> 0 | F2: =IF(COUNTIF('Start Set'!A:A, A2) > 0, 1, 0) -> 0 | H2: 1
A3: Automatisierte Integration von IoT-Geräten in IoT-Umgebungen | B3: M Reichel | C3: 2019 | D3: elib.uni-stuttgart.de | E3: =--(ROW(A3)<>MATCH(A3,$A:$A,0)) -> 0 | F3: =IF(COUNTIF('Start Set'!A:A, A3) > 0, 1, 0) -> 0 | G3: 1 | H3: 1
A4: Verbesserung von Robustheit und Ausfallsicherheit bei der Datenverarbeitung in IoT-Umgebungen | B4: T Schubert | C4: 2020 | D4: elib.uni-stuttgart.de | E4: =--(ROW(A4)<>MATCH(A4,$A:$A,0)) -> 0 | F4: =IF(COUNTIF('Start Set'!A:A, A4) > 0, 1, 0) -> 0 | H4: 1
A5: Studio e sviluppo di sistemi di manutenzione predittiva basati su industrial IoT | B5: G Temperini | C5: 2020 | D5: univpm.it | E5: =--(ROW(A5)<>MATCH(A5,$A:$A,0)) -> 0 | F5: =IF(COUNTIF('Start Set'!A:A, A5) > 0, 1, 0) -> 0 | H5: 1
A6: Physical-layer Jammer Detection in Multi-hop IoT Networks | B6: M Bag-Mohammadi | C6: 2020 | D6: durham-repository.worktribe.com | E6: =--(ROW(A6)<>MATCH(A6,$A:$A,0)) -> 0 | F6: =IF(COUNTIF('Start Set'!A:A, A6) > 0, 1, 0) -> 0 | H6: 1
A7: E2E-Aware Multi-Service Radio Resource Management for 5G New Radio: Radio Access and Resource Management Solutions | B7: AAMAA Esswie | C7: 2020 | D7: Aalborg University (aau.dk) | E7: =--(ROW(A7)<>MATCH(A7,$A:$A,0)) -> 0 | F7: =IF(COUNTIF('Start Set'!A:A, A7) > 0, 1, 0) -> 0 | H7: 1
A8: Intelligent and Low Overhead Network Synchronization over Large-Scale Industrial Internet of Things Systems | B8: P Jia | C8: 2020 | D8: ProQuest | E8: =--(ROW(A8)<>MATCH(A8,$A:$A,0)) -> 0 | F8: =IF(COUNTIF('Start Set'!A:A, A8) > 0, 1, 0) -> 0 | H8: 1
A9: Improving Response Time of Task Offloading by Random Forest Extra-Trees and Adaboost Classifiers in Mobile Fog Computing | B9: E Darbanian, D Rahbari, R Ghanizadeh… | C9: 2020 | D9: Jordanian Journal of … | E9: =--(ROW(A9)<>MATCH(A9,$A:$A,0)) -> 0 | F9: =IF(COUNTIF('Start Set'!A:A, A9) > 0, 1, 0) -> 0 | H9: 1
A10: Comparative Analysis of NoSQL Database's Activities and Scalability Investigation With Library Introspection | B10: CH Seo, B Tak | C10: 2020 | D10: Journal of The Korea Society of … | E10: =--(ROW(A10)<>MATCH(A10,$A:$A,0)) -> 0 | F10: =IF(COUNTIF('Start Set'!A:A, A10) > 0, 1, 0) -> 0 | H10: 1
A11: Real-Time Control Over Wireless Networks | B11: VP Modekurthy | C11: 2020 | D11: ProQuest (Book) | E11: =--(ROW(A11)<>MATCH(A11,$A:$A,0)) -> 0 | F11: =IF(COUNTIF('Start Set'!A:A, A11) > 0, 1, 0) -> 0 | H11: 1
A12: NGHIÊN CỨU GIẢI PHÁP ĐIỀU KHIỂN TRUY NHẬP PHƯƠNG TIỆN ƯU TIÊN TRÊN CỬA SỔ CẠNH TRANH CHO MẠNG CẢM BIẾN KHÔNG DÂY IoT ĐA SỰ KIỆN … | B12: NTT Hằng, VT Vinh | C12: 2021 | D12: Journal of Science and Technology on … | E12: =--(ROW(A12)<>MATCH(A12,$A:$A,0)) -> 0 | F12: =IF(COUNTIF('Start Set'!A:A, A12) > 0, 1, 0) -> 0 | H12: 1
A13: RETRACTED CHAPTER: Optimization of the Overlap Shortest-Path Routing for TSCH Networks | B13: J Caceres, MV Garcia | C13: 2021 | D13: Sustainable Systems: Selected Papers of WorldS4 … | E13: =--(ROW(A13)<>MATCH(A13,$A:$A,0)) -> 0 | F13: =IF(COUNTIF('Start Set'!A:A, A13) > 0, 1, 0) -> 0 | H13: 1
A14: Criterios de ubicación de algoritmos de inteligencia computacional en la web de las cosas: Revisión sistemática de la literatura | B14: LCER Parra, MÁN Zambrano… | C14: 2021 | D14: Innovación en … | E14: =--(ROW(A14)<>MATCH(A14,$A:$A,0)) -> 0 | F14: =IF(COUNTIF('Start Set'!A:A, A14) > 0, 1, 0) -> 0 | H14: 1
A15: Metode de planificare timp real pentru sisteme distribuite cu niveluri mixte de criticalitate | B15: EA Capotă, MV Micea | C15: 2021 | D15: UPT | E15: =--(ROW(A15)<>MATCH(A15,$A:$A,0)) -> 0 | F15: =IF(COUNTIF('Start Set'!A:A, A15) > 0, 1, 0) -> 0 | H15: 1
... A20: ХМАРНА АРХІТЕКТУРА ПЕРЕДАЧІ ДАНИХ… | B20: ОС Омельченко, НМ Луцька | C20: 2021 | D20: EBSCOhost | E20: =--(ROW(A20)<>MATCH(A20,$A:$A,0)) -> 0 | F20: =IF(COUNTIF('Start Set'!A:A, A20) > 0, 1, 0) -> 0 | H20: 1
A21: A survey of 802.15. 4 TSCH schedulers for a standardized industrial Internet of Things | B21: AR Urke, Ø Kure, K Øvsthus | C21: 2021 | D21: Sensors | E21: 1 | F21: =IF(COUNTIF('Start Set'!A:A, A21) > 0, 1, 0) -> 0 | H21: 1
A22: EDF Scheduling and Minimal-Overlap Shortest-Path Routing for Real-Time TSCH Networks | B22: M Gutiérrez Gaitán, L Almeida, PM Santos… | C22: 2021 | D22: recipp.ipp.pt | E22: =--(ROW(A22)<>MATCH(A22,$A:$A,0)) -> 0 | F22: =IF(COUNTIF('Start Set'!A:A, A22) > 0, 1, 0) -> 0 | H22: 1
A23: BAMSim Simulator | B23: RF Reale, JSB Martins | C23: 2021 | D23: arXiv preprint arXiv:2102.00273 | E23: =--(ROW(A23)<>MATCH(A23,$A:$A,0)) -> 0 | F23: =IF(COUNTIF('Start Set'!A:A, A23) > 0, 1, 0) -> 0 | H23: 1
A24: T2AS: Topology/Traffic Aware Scheduling to Optimize the End-to-end Delay in IEEE802. 154e-TSCH Networks | B24: E Mozaffari Ahrar, M Nassiri | C24: 2021 | D24: مجله مهندسی برق دانشگاه تبریز | E24: =--(ROW(A24)<>MATCH(A24,$A:$A,0)) -> 0 | F24: =IF(COUNTIF('Start Set'!A:A, A24) > 0, 1, 0) -> 0 | H24: 1
A25: AIoT for achieving sustainable development goals | B25: JM Corchado Rodríguez | C25: 2021 | E25: =--(ROW(A25)<>MATCH(A25,$A:$A,0)) -> 0 | F25: =IF(COUNTIF('Start Set'!A:A, A25) > 0, 1, 0) -> 0 | H25: 1
A26: Last mile delivery | B26: JM Corchado Rodríguez | C26: 2021 | E26: =--(ROW(A26)<>MATCH(A26,$A:$A,0)) -> 0 | F26: =IF(COUNTIF('Start Set'!A:A, A26) > 0, 1, 0) -> 0 | H26: 1
A27: IoT-Fog architectures in smart city applications: A survey | B27: SS Hajam, SA Sofi | C27: 2021 | D27: China Communications | E27: =--(ROW(A27)<>MATCH(A27,$A:$A,0)) -> 0 | F27: =IF(COUNTIF('Start Set'!A:A, A27) > 0, 1, 0) -> 0 | H27: 1
A28: Distributed Signal Processing in Digital Substations: Integrating High Sampling Rate Measurements at the Process-Level | B28: F Hohn | C28: 2021 | D28: diva-portal.org | E28: =--(ROW(A28)<>MATCH(A28,$A:$A,0)) -> 0 | F28: =IF(COUNTIF('Start Set'!A:A, A28) > 0, 1, 0) -> 0 | H28: 1
A29: Predictable Multiprocessor Platform for Safety-Critical Real-Time Systems | B29: PA Sigurðsson | C29: 2021 | D29: diva-portal.org | E29: =--(ROW(A29)<>MATCH(A29,$A:$A,0)) -> 0 | F29: =IF(COUNTIF('Start Set'!A:A, A29) > 0, 1, 0) -> 0 | H29: 1
A30: Intelligent aquaculture environment monitoring system based on LoRa communication technology. | B30: H Cai, F Li, P Lv, L Ran, L Zou | C30: 2021 | D30: INMATEH-Agricultural Engineering | E30: =--(ROW(A30)<>MATCH(A30,$A:$A,0)) -> 0 | F30: =IF(COUNTIF('Start Set'!A:A, A30) > 0, 1, 0) -> 0 | H30: 1
A31: Analysis of freertos overheads on periodic tasks | B31: BD Miranda, RS de Oliveira… | C31: 2021 | D31: … em Desempenho de … | E31: =--(ROW(A31)<>MATCH(A31,$A:$A,0)) -> 0 | F31: =IF(COUNTIF('Start Set'!A:A, A31) > 0, 1, 0) -> 0 | H31: 1
A32: Research on joint computation offloading and resource allocation strategy for mobile edge computing | B32: D Huang, YU Liyang, C Jue… | C32: 2021 | D32: Journal of East China … | E32: =--(ROW(A32)<>MATCH(A32,$A:$A,0)) -> 0 | F32: =IF(COUNTIF('Start Set'!A:A, A32) > 0, 1, 0) -> 0 | H32: 1
A33: A study on the VLC security at the physical layer for two indoor scenarios | B33: S Riurean | C33: 2021 | D33: MATEC Web of Conferences | E33: =--(ROW(A33)<>MATCH(A33,$A:$A,0)) -> 0 | F33: =IF(COUNTIF('Start Set'!A:A, A33) > 0, 1, 0) -> 0 | H33: 1
A34: Analysis and design of control plane functions for industrial internet of things | B34: D Fanucchi | C34: 2021 | D34: opus.bibliothek.uni-augsburg.de | E34: =--(ROW(A34)<>MATCH(A34,$A:$A,0)) -> 0 | F34: =IF(COUNTIF('Start Set'!A:A, A34) > 0, 1, 0) -> 0 | H34: 1
A35: A 3-hop Topology With TSCH Scheduling in Small and Dense WSNs or In-Vehicles WSNs | B35: RG Goh | C35: 2021 | D35: ProQuest | E35: =--(ROW(A35)<>MATCH(A35,$A:$A,0)) -> 0 | F35: =IF(COUNTIF('Start Set'!A:A, A35) > 0, 1, 0) -> 0 | H35: 1
A36: Long-Term Stable Communication in Centrally Scheduled Low-Power Wireless Networks | B36: O Harms | C36: 2021 | D36: ProQuest | E36: =--(ROW(A36)<>MATCH(A36,$A:$A,0)) -> 0 | F36: =IF(COUNTIF('Start Set'!A:A, A36) > 0, 1, 0) -> 0 | H36: 1
A37: Master Thesis Computer Science | B37: N Traffic | C37: 2022 | D37: hs-esslingen.de | E37: =--(ROW(A37)<>MATCH(A37,$A:$A,0)) -> 0 | F37: =IF(COUNTIF('Start Set'!A:A, A37) > 0, 1, 0) -> 0 | H37: 1
A38: 面向海洋节能边缘计算的任务卸载研究 | B38: 蒋欣秀, 常俊, 李波, 杨志军, 丁洪伟 | C38: 2022 | D38: 计算机工程与科学 | E38: =--(ROW(A38)<>MATCH(A38,$A:$A,0)) -> 0 | F38: =IF(COUNTIF('Start Set'!A:A, A38) > 0, 1, 0) -> 0 | H38: 1
... A50: Oakestra white paper: An orchestrator for edge computing | B50: G Bartolomeo, M Yosofie, S Bäurle… | C50: 2022 | D50: arXiv preprint | E50: =--(ROW(A50)<>MATCH(A50,$A:$A,0)) -> 0 | F50: =IF(COUNTIF('Start Set'!A:A, A50) > 0, 1, 0) -> 0 | H50: 1
A51: Developing educational curricula for digital transformation V2 | B51: JM Corchado | C51: 2022 | E51: =--(ROW(A51)<>MATCH(A51,$A:$A,0)) -> 0 | F51: =IF(COUNTIF('Start Set'!A:A, A51) > 0, 1, 0) -> 0 | H51: 1
A52: Blockchain for smart manufacturing systems: a survey | B52: Z Song, J Zhu | C52: 2022 | D52: Chinese Management Studies | E52: =--(ROW(A52)<>MATCH(A52,$A:$A,0)) -> 0 | F52: =IF(COUNTIF('Start Set'!A:A, A52) > 0, 1, 0) -> 0 | H52: 1
A53: A relative torsional vibration monitoring method for intelligent ships and associated error analysis | B53: AN Yunsheng, C Huang, Z Wu, Q Li, J Li… | C53: 2022 | D53: Insight-Non … | E53: =--(ROW(A53)<>MATCH(A53,$A:$A,0)) -> 0 | F53: =IF(COUNTIF('Start Set'!A:A, A53) > 0, 1, 0) -> 0 | H53: 1
A54: DOCUMENTS & INFORMATIONS | B54: A No | C54: 2022 | D54: transact-ecsel.eu / HeinOnline | E54: =--(ROW(A54)<>MATCH(A54,$A:$A,0)) -> 0 | F54: =IF(COUNTIF('Start Set'!A:A, A54) > 0, 1, 0) -> 0 | H54: 1
A55: Multi-criteria decision support for energy-efficient IoT edge computing offloading | B55: A Jaddoa | C55: 2022 | D55: University of Greenwich | E55: =--(ROW(A55)<>MATCH(A55,$A:$A,0)) -> 0 | F55: =IF(COUNTIF('Start Set'!A:A, A55) > 0, 1, 0) -> 0 | H55: 1
...

Sheet Iteration 1 - Backward
A1: Title | B1: Authors | C1: Year | D1: Venue | E1: D | F1: DS | G1: DF | H1: EC1 | I1: EC2 | J1: EC3 | K1: EC4 | L1: EC5 | M1: EC6 | N1: IC1
A2: Networks of Waiting Lines | B2: Jackson, J.R. | C2: 1957 | D2: Operations Research | E2: =--(ROW(A2)<>MATCH(A2,$A:$A,0)) -> 0 | F2: =IF(COUNTIF('Start Set'!A:A, A2) > 0, 1, 0) -> 0 | G2: =IF(COUNTIF('Iteration 1 - Forward'!A:A, A2) > 0, 1, 0) -> 0 | H2: 1
A3: Validity of the Single-Processor Approach to Achieving Large-Scale Computing Requirements | B3: Amdahl, G. | C3: 1967 | D3: Computer Design | E3: =--(ROW(A3)<>MATCH(A3,$A:$A,0)) -> 0 | F3: =IF(COUNTIF('Start Set'!A:A, A3) > 0, 1, 0) -> 0 | G3: =IF(COUNTIF('Iteration 1 - Forward'!A:A, A3) > 0, 1, 0) -> 0 | H3: 1
A4: Complexity of Computer Computations | B4: Karp, R.M. | C4: 1972 | D4: Symposium on Complexity of Computer Computations | E4: =--(ROW(A4)<>MATCH(A4,$A:$A,0)) -> 0 | F4: =IF(COUNTIF('Start Set'!A:A, A4) > 0, 1, 0) -> 0 | G4: =IF(COUNTIF('Iteration 1 - Forward'!A:A, A4) > 0, 1, 0) -> 0 | H4: 1
A5: Queueing Systems Vol. I: Theory | B5: Kleinrock, L. | C5: 1975 | D5: Wiley Interscience | E5: =--(ROW(A5)<>MATCH(A5,$A:$A,0)) -> 0 | F5: =IF(COUNTIF('Start Set'!A:A, A5) > 0, 1, 0) -> 0 | G5: =IF(COUNTIF('Iteration 1 - Forward'!A:A, A5) > 0, 1, 0) -> 0 | H5: 1
A6: Reception through Nakagami fading multipath channels with random delays | B6: Charash, U. | C6: 1979 | D6: IEEE Transactions on Communications | E6: =--(ROW(A6)<>MATCH(A6,$A:$A,0)) -> 0 | F6: =IF(COUNTIF('Start Set'!A:A, A6) > 0, 1, 0) -> 0 | G6: =IF(COUNTIF('Iteration 1 - Forward'!A:A, A6) > 0, 1, 0) -> 0 | H6: 1
A7: Some complexity results about packet radio networks | B7: Arikan, E. | C7: 1984 | D7: IEEE Transactions on Information Theory | E7: =--(ROW(A7)<>MATCH(A7,$A:$A,0)) -> 0 | F7: =IF(COUNTIF('Start Set'!A:A, A7) > 0, 1, 0) -> 0 | G7: =IF(COUNTIF('Iteration 1 - Forward'!A:A, A7) > 0, 1, 0) -> 0 | H7: 1
A8: Minimization Methods for Non-Differentiable Functions | B8: Shor, N.Z. | C8: 1985 | D8: Springer-Verlag | E8: =--(ROW(A8)<>MATCH(A8,$A:$A,0)) -> 0 | F8: =IF(COUNTIF('Start Set'!A:A, A8) > 0, 1, 0) -> 0 | G8: =IF(COUNTIF('Iteration 1 - Forward'!A:A, A8) > 0, 1, 0) -> 0 | H8: 1
A9: Congestion Avoidance and Control | B9: Jacobson, V. | C9: 1988 | D9: ACM SIGCOMM Symposium | E9: =--(ROW(A9)<>MATCH(A9,$A:$A,0)) -> 0 | F9: =IF(COUNTIF('Start Set'!A:A, A9) > 0, 1, 0) -> 0 | G9: =IF(COUNTIF('Iteration 1 - Forward'!A:A, A9) > 0, 1, 0) -> 0 | H9: 1
A10: Probabilistic clock synchronization | B10: Cristian, F. | C10: 1989 | D10: Distributed Computing | E10: =--(ROW(A10)<>MATCH(A10,$A:$A,0)) -> 0 | F10: =IF(COUNTIF('Start Set'!A:A, A10) > 0, 1, 0) -> 0 | G10: =IF(COUNTIF('Iteration 1 - Forward'!A:A, A10) > 0, 1, 0) -> 0 | H10: 1
A11: The Tangram stream query processing system | B11: Parker, D.S.; Muntz, R.R.; Chau, H.L. | C11: 1989 | D11: IEEE International Conference on Data Engineering | E11: =--(ROW(A11)<>MATCH(A11,$A:$A,0)) -> 0 | F11: =IF(COUNTIF('Start Set'!A:A, A11) > 0, 1, 0) -> 0 | G11: =IF(COUNTIF('Iteration 1 - Forward'!A:A, A11) > 0, 1, 0) -> 0 | H11: 1
A12: Priority inheritance protocols: An approach to real-time synchronization | B12: Sha, L.; Rajkumar, R.; Lehoczky, J. | C12: 1990 | D12: IEEE Transactions on Computers | E12: =--(ROW(A12)<>MATCH(A12,$A:$A,0)) -> 0 | F12: =IF(COUNTIF('Start Set'!A:A, A12) > 0, 1, 0) -> 0 | G12: =IF(COUNTIF('Iteration 1 - Forward'!A:A, A12) > 0, 1, 0) -> 0 | H12: 1
A13: Stream Data Analysis in Prolog | B13: Parker, D.S. | C13: 1990 | D13: MIT Press (The Practice of Prolog) | E13: =--(ROW(A13)<>MATCH(A13,$A:$A,0)) -> 0 | F13: =IF(COUNTIF('Start Set'!A:A, A13) > 0, 1, 0) -> 0 | G13: =IF(COUNTIF('Iteration 1 - Forward'!A:A, A13) > 0, 1, 0) -> 0 | H13: 1
A14: Internet time synchronization: The network time protocol | B14: Mills, D.L. | C14: 1991 | D14: IEEE Transactions on Communications | E14: =--(ROW(A14)<>MATCH(A14,$A:$A,0)) -> 0 | F14: =IF(COUNTIF('Start Set'!A:A, A14) > 0, 1, 0) -> 0 | G14: =IF(COUNTIF('Iteration 1 - Forward'!A:A, A14) > 0, 1, 0) -> 0 | H14: 1
A15: Statistical Signal Processing Detection Estimation and Time Series Analysis | B15: Scharf, C.D.L. | C15: 1991 | D15: Addison-Wesley | E15: =--(ROW(A15)<>MATCH(A15,$A:$A,0)) -> 0 | F15: =IF(COUNTIF('Start Set'!A:A, A15) > 0, 1, 0) -> 0 | G15: =IF(COUNTIF('Iteration 1 - Forward'!A:A, A15) > 0, 1, 0) -> 0 | H15: 1 | I15: 1
A16: Data Networks (2nd Ed.) | B16: Bertsekas, D.; Gallager, R. | C16: 1992 | D16: Prentice-Hall | E16: =--(ROW(A16)<>MATCH(A16,$A:$A,0)) -> 0 | F16: =IF(COUNTIF('Start Set'!A:A, A16) > 0, 1, 0) -> 0 | G16: =IF(COUNTIF('Iteration 1 - Forward'!A:A, A16) > 0, 1, 0) -> 0 | H16: 1 | I16: 1
A17: A simple distributed autonomous power control algorithm and its convergence | B17: Foschini, G.J.; Miljanic, Z. | C17: 1993 | D17: IEEE Transactions on Vehicular Technology | E17: =--(ROW(A17)<>MATCH(A17,$A:$A,0)) -> 0 | F17: =IF(COUNTIF('Start Set'!A:A, A17) > 0, 1, 0) -> 0 | G17: =IF(COUNTIF('Iteration 1 - Forward'!A:A, A17) > 0, 1, 0) -> 0 | H17: 1
A18: Fundamentals of Statistical Signal Processing Volume 1 | B18: Kay, S.M. | C18: 1993 | D18: Prentice-Hall | E18: =--(ROW(A18)<>MATCH(A18,$A:$A,0)) -> 0 | F18: =IF(COUNTIF('Start Set'!A:A, A18) > 0, 1, 0) -> 0 | G18: =IF(COUNTIF('Iteration 1 - Forward'!A:A, A18) > 0, 1, 0) -> 0 | H18: 1 | I18: 1
A19: Fundamentals of Statistical Signal Processing: Estimation Theory | B19: Kay, S.M. | C19: 1993 | D19: Prentice-Hall | E19: =--(ROW(A19)<>MATCH(A19,$A:$A,0)) -> 0 | F19: =IF(COUNTIF('Start Set'!A:A, A19) > 0, 1, 0) -> 0 | G19: =IF(COUNTIF('Iteration 1 - Forward'!A:A, A19) > 0, 1, 0) -> 0 | H19: 1 | I19: 1
A20: Holistic schedulability analysis for distributed hard real-time systems | B20: Tindell, K.; Clark, J. | C20: 1994 | D20: Microprocessing and Microprogramming | E20: =--(ROW(A20)<>MATCH(A20,$A:$A,0)) -> 0 | F20: =IF(COUNTIF('Start Set'!A:A, A20) > 0, 1, 0) -> 0 | G20: =IF(COUNTIF('Iteration 1 - Forward'!A:A, A20) > 0, 1, 0) -> 0 | H20: 1
A21: An Introduction to Signal Detection and Estimation | B21: Poor, H.V. | C21: 1994 | D21: Springer | E21: =--(ROW(A21)<>MATCH(A21,$A:$A,0)) -> 0 | F21: =IF(COUNTIF('Start Set'!A:A, A21) > 0, 1, 0) -> 0 | G21: =IF(COUNTIF('Iteration 1 - Forward'!A:A, A21) > 0, 1, 0) -> 0 | H21: 1
A22: The TSQL2 Temporal Query Language | B22: Snodgrass, R.T.; Ahn, I.; Ariav, G.; Batory, D.S.; Clifford, J.; Dyreson, C.E.; Elmasri, R.; Grandi, F.; Jensen, C.S.; Käfer, W.; Kline, N.; Kulkanri, K.; Leung, C.Y.T.; Lorentzos, N.; Roddick, J.F.; Segev, A.; Soo, M.D.; Sripada, S.M. | C22: 1995 | D22: Kluwer Academic | E22: =--(ROW(A22)<>MATCH(A22,$A:$A,0)) -> 0 | F22: =IF(COUNTIF('Start Set'!A:A, A22) > 0, 1, 0) -> 0 | G22: =IF(COUNTIF('Iteration 1 - Forward'!A:A, A22) > 0, 1, 0) -> 0 | H22: 1
A23: The pipes and filters architecture | B23: Meunier, R. | C23: 1995 | D23: Pattern Languages of Program Design (ACM Press/Addison-Wesley) | E23: =--(ROW(A23)<>MATCH(A23,$A:$A,0)) -> 0 | F23: =IF(COUNTIF('Start Set'!A:A, A23) > 0, 1, 0) -> 0 | G23: =IF(COUNTIF('Iteration 1 - Forward'!A:A, A23) > 0, 1, 0) -> 0 | H23: 1
A24: Aperiodic servers in a deadline scheduling environment | B24: Ghazalie, T.M.; Baker, T.P. | C24: 1995 | D24: Real-Time Systems | E24: =--(ROW(A24)<>MATCH(A24,$A:$A,0)) -> 0 | F24: =IF(COUNTIF('Start Set'!A:A, A24) > 0, 1, 0) -> 0 | G24: =IF(COUNTIF('Iteration 1 - Forward'!A:A, A24) > 0, 1, 0) -> 0 | H24: 1
A25: Operating system architecture using multiple priority lightweight kernel task based interrupt handling | B25: Bunnell, M. | C25: 1995 | D25: US Patent 5469571 | E25: =--(ROW(A25)<>MATCH(A25,$A:$A,0)) -> 0 | F25: =IF(COUNTIF('Start Set'!A:A, A25) > 0, 1, 0) -> 0 | G25: =IF(COUNTIF('Iteration 1 - Forward'!A:A, A25) > 0, 1, 0) -> 0 | H25: 1 | I25: 1
A26: Advanced Database Systems | B26: Zaniolo, C.; Ceri, S.; Faloutsos, C.; Snodgrass, R.T.; Subrahmanian, V.S.; Zicari, R. | C26: 1997 | D26: Morgan Kaufmann | E26: =--(ROW(A26)<>MATCH(A26,$A:$A,0)) -> 0 | F26: =IF(COUNTIF('Start Set'!A:A, A26) > 0, 1, 0) -> 0 | G26: =IF(COUNTIF('Iteration 1 - Forward'!A:A, A26) > 0, 1, 0) -> 0 | H26: 1
A27: IEEE Standard for Wireless LAN Medium Access Control (MAC) and Physical Layer (PHY) Specifications | C27: 1997 | D27: IEEE Std 802.11-1997 | E27: =--(ROW(A27)<>MATCH(A27,$A:$A,0)) -> 0 | F27: =IF(COUNTIF('Start Set'!A:A, A27) > 0, 1, 0) -> 0 | G27: =IF(COUNTIF('Iteration 1 - Forward'!A:A, A27) > 0, 1, 0) -> 0 | H27: 1 | I27: 1
A28: Integer Programming | B28: Wolsey, L. | C28: 1998 | D28: Wiley | E28: =--(ROW(A28)<>MATCH(A28,$A:$A,0)) -> 0 | F28: =IF(COUNTIF('Start Set'!A:A, A28) > 0, 1, 0) -> 0 | G28: =IF(COUNTIF('Iteration 1 - Forward'!A:A, A28) > 0, 1, 0) -> 0 | H28: 1
A29: Lipschitz Algebras | B29: Weaver, N. | C29: 1999 | D29: World Scientific | E29: =--(ROW(A29)<>MATCH(A29,$A:$A,0)) -> 0 | F29: =IF(COUNTIF('Start Set'!A:A, A29) > 0, 1, 0) -> 0 | G29: =IF(COUNTIF('Iteration 1 - Forward'!A:A, A29) > 0, 1, 0) -> 0 | H29: 1
A30: Performance analysis of the IEEE 802.11 distributed coordination function | B30: Bianchi, G. | C30: 2000 | D30: IEEE Journal on Selected Areas in Communications | E30: =--(ROW(A30)<>MATCH(A30,$A:$A,0)) -> 0 | F30: =IF(COUNTIF('Start Set'!A:A, A30) > 0, 1, 0) -> 0 | G30: =IF(COUNTIF('Iteration 1 - Forward'!A:A, A30) > 0, 1, 0) -> 0 | H30: 1
A31: The capacity of wireless networks | B31: Gupta, P.; Kumar, P.R. | C31: 2000 | D31: IEEE Transactions on Information Theory | E31: =--(ROW(A31)<>MATCH(A31,$A:$A,0)) -> 0 | F31: =IF(COUNTIF('Start Set'!A:A, A31) > 0, 1, 0) -> 0 | G31: =IF(COUNTIF('Iteration 1 - Forward'!A:A, A31) > 0, 1, 0) -> 0 | H31: 1
A32: Matrix analysis and applied linear algebra | B32: Meyer, C.D. | C32: 2000 | D32: SIAM | E32: =--(ROW(A32)<>MATCH(A32,$A:$A,0)) -> 0 | F32: =IF(COUNTIF('Start Set'!A:A, A32) > 0, 1, 0) -> 0 | G32: =IF(COUNTIF('Iteration 1 - Forward'!A:A, A32) > 0, 1, 0) -> 0 | H32: 1
A33: Time Granularities in Databases Data Mining and Temporal Reasoning | B33: Bettini, C.; Jajodia, S.; Wang, S.X. | C33: 2000 | D33: Springer | E33: =--(ROW(A33)<>MATCH(A33,$A:$A,0)) -> 0 | F33: =IF(COUNTIF('Start Set'!A:A, A33) > 0, 1, 0) -> 0 | G33: =IF(COUNTIF('Iteration 1 - Forward'!A:A, A33) > 0, 1, 0) -> 0 | H33: 1
A34: Real-Time Systems | B34: Liu, J.W.S. | C34: 2000 | D34: Prentice-Hall | E34: =--(ROW(A34)<>MATCH(A34,$A:$A,0)) -> 0 | F34: =IF(COUNTIF('Start Set'!A:A, A34) > 0, 1, 0) -> 0 | G34: =IF(COUNTIF('Iteration 1 - Forward'!A:A, A34) > 0, 1, 0) -> 0 | H34: 1 | I34: 1
A35: Performance analysis of the IEEE 802.11 distributed coordination function | B35: Bianchi, G. | C35: 2000 | D35: IEEE Journal on Selected Areas in Communications | E35: =--(ROW(A35)<>MATCH(A35,$A:$A,0)) -> 1 | F35: =IF(COUNTIF('Start Set'!A:A, A35) > 0, 1, 0) -> 0 | G35: =IF(COUNTIF('Iteration 1 - Forward'!A:A, A35) > 0, 1, 0) -> 0 | H35: 1
A36: A new approach to channel access scheduling for ad hoc networks | B36: Bao, L.; Garcia-Luna-Aceves, J. | C36: 2001 | D36: ACM International Conference on Mobile Computing and Networking (MobiCom) | E36: =--(ROW(A36)<>MATCH(A36,$A:$A,0)) -> 0 | F36: =IF(COUNTIF('Start Set'!A:A, A36) > 0, 1, 0) -> 0 | G36: =IF(COUNTIF('Iteration 1 - Forward'!A:A, A36) > 0, 1, 0) -> 0 | H36: 1
A37: Highly-resilient energy-efficient multipath routing in wireless sensor networks | B37: Ganesan, D.; Govindan, R.; Shenker, S.; Estrin, D. | C37: 2001 | D37: ACM SIGMOBILE Mobile Computing and Communications Review | E37: =--(ROW(A37)<>MATCH(A37,$A:$A,0)) -> 0 | F37: =IF(COUNTIF('Start Set'!A:A, A37) > 0, 1, 0) -> 0 | G37: =IF(COUNTIF('Iteration 1 - Forward'!A:A, A37) > 0, 1, 0) -> 0 | H37: 1
A38: HIP: Hybrid interrupt-polling for the network interface | B38: Dovrolis, C.; Thayer, B.; Ramanathan, P. | C38: 2001 | D38: ACM SIGOPS Operating Systems Review | E38: =--(ROW(A38)<>MATCH(A38,$A:$A,0)) -> 0 | F38: =IF(COUNTIF('Start Set'!A:A, A38) > 0, 1, 0) -> 0 | G38: =IF(COUNTIF('Iteration 1 - Forward'!A:A, A38) > 0, 1, 0) -> 0 | H38: 1
A39: Resource partition for real-time systems | B39: Mok, A.; Feng, X.; Chen, D. | C39: 2001 | D39: IEEE RTAS | E39: =--(ROW(A39)<>MATCH(A39,$A:$A,0)) -> 0 | F39: =IF(COUNTIF('Start Set'!A:A, A39) > 0, 1, 0) -> 0 | G39: =IF(COUNTIF('Iteration 1 - Forward'!A:A, A39) > 0, 1, 0) -> 0 | H39: 1
A40: A bandwidth inheritance algorithm for real-time task synchronization in open systems | B40: Lamastra, G.; Lipari, G.; Abeni, L. | C40: 2001 | D40: IEEE RTSS | E40: =--(ROW(A40)<>MATCH(A40,$A:$A,0)) -> 0 | F40: =IF(COUNTIF('Start Set'!A:A, A40) > 0, 1, 0) -> 0 | G40: =IF(COUNTIF('Iteration 1 - Forward'!A:A, A40) > 0, 1, 0) -> 0 | H40: 1
...

Sheet Finesort 1
A1: F/B | B1: Title | C1: Authors | D1: Year | E1: Venue | F1: Source 1 | G1: Source 2 | H1: Comment | I1: Numerical | J1: Alfabetical
A2: B | B2: A systematic survey of Industrial Internet of Things Security: Requirements and Fog Computing opportunities | C2: Tange, K.; De Donno, M.; Fafoutis, X.; Dragoni, N. | D2: 2020 | E2: IEEE Communications Surveys & Tutorials | F2: x | G2: x | H2: No Use Case+Req | I2: 0 | J2: 0
A3: B | B3: Challenges and opportunities in securing the industrial internet of things | C3: Serror, M.; Hack, S.; Henze, M.; Schuba, M.; Wehrle, K. | D3: 2020 | E3: IEEE Transactions on Industrial Informatics | F3: TABLE I COMPARISON B ETWEEN CONSUMER AND IIOT | G3: x | H3: No Use Case+Req | I3: 1 | J3: 1
A4: B | B4: Emerging wireless technologies for Internet of Things applications: Opportunities and challenges | C4: Mollah, M.B.; Zeadally, S.; Azad, M.A.K. | D4: 2020 | E4: Encyclopedia of Wireless Networks (Springer) | F4: x | G4: x | H4: Not Peer-Rev. Conf./Jour. | I4: 0 | J4: 1
A5: B | B5: Evaluation of Multi-Connectivity Schemes for URLLC Traffic over WiFi and LTE | C5: Suer, M.-T.; et al. | D5: 2020 | E5: IEEE WCNC | F5: TABLE I: QoS requirements for industrial applications as defined by 3GPP [3]. | G5: TABLE II: Requirements for URLLC for industrial applications as specified by Industry 4.0 Forum [5]. | H5: Not IoT | I5: 1 | J5: 0
A6: B | B6: Measures to Improve the Accuracy and Reliability of Clock Synchronization in Time-Sensitive Networking | C6: Zhu, H.; Liu, K.; Yan, Y.; Zhang, H.; Huang, T. | D6: 2020 | E6: IEEE Access | F6: TABLE 1. Comparison of several clock synchronization methods. | G6: x | H6: Not IoT | I6: 1 | J6: 0
A7: B | B7: Visible light communication in 6G: Advances challenges and prospects | C7: Chi, N.; Zhou, Y.; Wei, Y.; Hu, F. | D7: 2020 | E7: IEEE Vehicular Technology Magazine | F7: Figure 7 The distribution demands of VLC transmission distances and data transmission rates in different application fields. V2X: vehicle to everything. | G7: x | H7: Not IoT | I7: 1 | J7: 0
A8: B | B8: A survey of 802.15. 4 TSCH schedulers for a standardized industrial Internet of Things | C8: AR Urke, Ø Kure, K Øvsthus | D8: 2021 | E8: Sensors | F8: x | G8: x | H8: Duplicate | I8: 1 | J8: 0
A9: B | B9: A garden of cyber physical systems: Requirements challenges and implementation aspects | C9: Demir, M.O.; Pusane, A.E.; Dartmann, G.; Ascheid, G.; Kurt, G.K. | D9: 2020 | E9: IEEE Internet of Things Magazine | F9: Figure 3. Flowers of the CPS applications. Their leaves and length of roots indicate the specific requirements of application: a) IWSNs; b) smart grid; c) smart healthcare; d) V2X communications. | G9: x | H9: No Use Case+Req | I9: 0 | J9: 1
A10: B | B10: Performance of 5G Trials for Industrial Automation | C10: Ansari, J.; et al. | D10: 2022 | E10: Electronics | F10: Table 1 | G10: x | H10: Not IoT, MDPI Q2 | I10: 1 | J10: 0
A12: F | B12: MAC protocols for industrial delay-sensitive applications in industry 4.0: Exploring challenges protocols and requirements | C12: A Chehri | D12: 2021 | E12: Procedia Computer Science (Elsevier) | F12: x | G12: x | H12: Not Peer-Rev. Conf./Jour. | I12: x
A13: F | B13: Smart Factory based on IIoT: Applications Communication Networks and Cybersecurity | C13: YS Sheet, MY Thanoun | D13: 2024 | E13: International Journal of … (ResearchGate) | F13: x | G13: x | H13: Not Peer-Rev. Conf./Jour. | I13: 1 | J13: 1
A14: F | B14: Subcarrier power control for URLLC communication system via multi-agent deep reinforcement learning in IoT network | C14: H Wang, X Li, F Luo, J Li | D14: 2024 | E14: International Journal of (Inderscience) | F14: x | G14: x | H14: Not Peer-Rev. Conf./Jour. | I14: 1 | J14: 0
A15: F | B15: Toward Low-Latency Cross-Modal Communication: A Flexible Prediction Scheme | C15: Y Chen, P Li, A Li, D Wu, L Zhou… | D15: 2024 | E15: IEEE Transactions on … | F15: TABLE I COMPARISON OF BASIC R EQUIREMENTS FOR DIFFERENT MULTI-MODAL SERVICES | G15: Fig. 1. Two challenging problems for prediction in cross-modal communication. Firstly, the prediction framework lacks the flexibility to be applied to multi-modal services with diversity. Secondly, it is difficult to fully explore and effectively utilize the correlation features of multi-modal signals for accurate cross-modal signal prediction. | H15: Not IoT | I15: 1 | J15: 0
A16: F | B16: Delay and reliability analysis of p-persistent carrier sense multiple access for multi-event industrial wireless sensor networks | C16: NTT Hang, NC Trinh, NT Ban, M Raza… | D16: 2020 | E16: IEEE Sensors Journal | F16: TABLE I QOS REQUIREMENTS FOR DIFFERENT PRIORITY APPLICATIONS | G16: x | H16: Not IoT | I16: 1 | J16: 1
A17: F | B17: Cloud–fog automation: Heterogenous applications over new-generation infrastructure of virtualized computing and converged networks | C17: H Lyu, J Yan, J Zhang, Z Pang, G Yang… | D17: 2024 | E17: IEEE Industrial Electronics Magazine | F17: FIGURE 3 – The selected representative automation application cases for Cloud-Fog Automation verification. | G17: x | H17: Not IoT | I17: 1 | J17: 0
A19: B | B19: Comparing Wi-Fi 6 and 5G Downlink Performance for Industrial IoT | C19: Maldonado, R.; et al. | D19: 2021 | E19: IEEE Access | F19: TABLE 1. Considered IIoT reference applications, example use-cases could be motion control (I), collaborative AGVs or robotic control (II and III), and asset/process monitoring or autonomous AGVs (IV). | G19: x | H19: OK | I19: 1 | J19: 0
A20: B | B20: Investigating messaging protocols for the Internet of Things (IoT) | C20: Al-Masri, E.; Kalyanam, K.R.; Batts, J.; Kim, J.; Singh, S.; Vo, T.; Yan, C. | D20: 2020 | E20: IEEE Access | F20: TABLE 2. IoT application range requirements [120]–[123], [130]–[140]. | G20: x | H20: OK | I20: 1 | J20: 0
A22: F | B22: Real-time performance of industrial IoT communication technologies: A review | C22: I Behnke, H Austad | D22: 2023 | E22: IEEE Internet of Things Journal | F22: TABLE I IIOT SCENARIO CLASSES | G22: x | H22: OK, has mapped use case -> technologies already | I22: 0 | J22: 1
A23: F | B23: A survey of 802.15.4 TSCH schedulers for a standardized Industrial Internet of Things | C23: Urke, A.R.; Kure, Ø.; Øvsthus, K. | D23: 2022 | E23: Sensors | F23: Table 1 | G23: x | H23: OK, MDPI Q1 | I23: 1 | J23: 0
A24: F | B24: Intelligent and low overhead network synchronization for large-scale industrial IoT systems in the 6G era | C24: X Wang, P Jia, X Shen, HV Poor | D24: 2022 | E24: IEEE Network | F24: TABLE 1. Application-dependent synchronization requirements in large-scale IIoT systems. | G24: x | H24: OK | I24: 1 | J24: 0
A25: F | B25: The computing continuum: Past present and future | C25: LF Bittencourt, R Rodrigues-Filho, J Spillner… | D25: 2025 | E25: Computer Science Review | F25: Table 4 Expected requirements for emerging use cases | G25: Table 3 Distributed computing infrastructures in an updated, snapshot perspective: how each type of system currently presents itself to the users in terms of access latency, location of the infrastructure, computational and storage capacity, what is the cost to access each infrastructure, connectivity/reliability, and if the expected performance guarantees for each type of system. | H25: OK | I25: 1 | J25: 0
A26: F | B26: URLLC and eMBB in 5G industrial IoT: A survey | C26: BS Khan, S Jangsher, A Ahmed | D26: 2022 | E26: IEEE Open Journal of the Communications Society | F26: TABLE 4. URLLC and eMBB based B5G-IIoT applications; Lat.: latency, Rel.: reliability, Tp.: throughput, cell dens.: cell density. | G26: x | H26: OK | I26: 1 | J26: 0
A27: F | B27: Strategies for assuring low latency scalability and interoperability in edge computing and TSN networks for critical IIoT services | C27: DL Gomez, GA Montoya, C Lozano-Garzon | D27: 2023 | E27: IEEE Access | F27: TABLE 1. Network requirements for industrial services [3]. | G27: x | H27: OK | I27: 1 | J27: 0
B29: =SUM(1191+568) -> 1759 | C29: Unique rows checked

Sheet Iteration 2 - Forward-Forward
A1: Title | B1: Authors | C1: Year | D1: Venue | E1: D | F1: DS | G1: DF | H1: DB | I1: EC1 | J1: EC2 | K1: EC3 | L1: EC4 | M1: EC5 | N1: EC6 | O1: IC1
A2: 基于增强型最大比例混合接收机的硅基调制器线性度补偿方法 | B2: 秦军， 陶源盛， 金明， 韩昌灏， 李月琴， 孙剑… | C2: 2023 | D2: Acta Optica … | E2: =--(ROW(A2)<>MATCH(A2,$A:$A,0)) -> 0 | F2: =IF(COUNTIF('Start Set'!A:A, A2) > 0, 1, 0) -> 0 | G2: =IF(COUNTIF('Iteration 1 - Forward'!A:A, A2) > 0, 1, 0) -> 0 | H2: =IF(COUNTIF('Iteration 1 - Backward'!A:A, A2) > 0, 1, 0) -> 0 | L2: 1
A3: PrioMQTT: A prioritized version of the MQTT protocol | B3: G Patti; L Leonardi; G Testa; LL Bello | C3: 2024 | D3: Computer Communications (Elsevier) | E3: =--(ROW(A3)<>MATCH(A3,$A:$A,0)) -> 0 | F3: =IF(COUNTIF('Start Set'!A:A, A3) > 0, 1, 0) -> 1 | G3: =IF(COUNTIF('Iteration 1 - Forward'!A:A, A3) > 0, 1, 0) -> 1 | H3: =IF(COUNTIF('Iteration 1 - Backward'!A:A, A3) > 0, 1, 0) -> 0
A4: A Dynamic IIoT Framework Based on the Publish–Subscribe Paradigm | B4: I Ungurean; NC Gaitan | C4: 2023 | D4: Sensors (MDPI) | E4: =--(ROW(A4)<>MATCH(A4,$A:$A,0)) -> 0 | F4: =IF(COUNTIF('Start Set'!A:A, A4) > 0, 1, 0) -> 0 | G4: =IF(COUNTIF('Iteration 1 - Forward'!A:A, A4) > 0, 1, 0) -> 1 | H4: =IF(COUNTIF('Iteration 1 - Backward'!A:A, A4) > 0, 1, 0) -> 0
A5: Subcarrier power control for URLLC communication system via multi-agent deep reinforcement learning in IoT network | B5: H Wang, X Li, F Luo, J Li… | C5: 2024 | D5: International Journal of … | E5: =--(ROW(A5)<>MATCH(A5,$A:$A,0)) -> 0 | F5: =IF(COUNTIF('Start Set'!A:A, A5) > 0, 1, 0) -> 0 | G5: =IF(COUNTIF('Iteration 1 - Forward'!A:A, A5) > 0, 1, 0) -> 1 | H5: =IF(COUNTIF('Iteration 1 - Backward'!A:A, A5) > 0, 1, 0) -> 0
A6: Robust Networked Control Adopting Prediction-Compensation Mechanism for IoT-Based Building Field-Level Control Concerning Network Uncertainties | B6: X Li, H Li, J Cao, S Wang | C6: 2025 | D6: IEEE Internet of Things Journal | E6: =--(ROW(A6)<>MATCH(A6,$A:$A,0)) -> 0 | F6: =IF(COUNTIF('Start Set'!A:A, A6) > 0, 1, 0) -> 0 | G6: =IF(COUNTIF('Iteration 1 - Forward'!A:A, A6) > 0, 1, 0) -> 1 | H6: =IF(COUNTIF('Iteration 1 - Backward'!A:A, A6) > 0, 1, 0) -> 0
A7: Beyond diagonal RIS-aided wireless communications systems: State-of-the-art and future research directions | B7: O Maraqa, MH Khoshafa, OO Oyerinde… | C7: 2025 | D7: arXiv preprint | E7: =--(ROW(A7)<>MATCH(A7,$A:$A,0)) -> 0 | F7: =IF(COUNTIF('Start Set'!A:A, A7) > 0, 1, 0) -> 0 | G7: =IF(COUNTIF('Iteration 1 - Forward'!A:A, A7) > 0, 1, 0) -> 0 | H7: =IF(COUNTIF('Iteration 1 - Backward'!A:A, A7) > 0, 1, 0) -> 0 | J7: 1
A8: Edge General Intelligence Through World Models and Agentic AI: Fundamentals, Solutions, and Challenges | B8: C Zhao, G Liu, R Zhang, Y Liu, J Wang, J Kang… | C8: 2025 | D8: arXiv preprint | E8: =--(ROW(A8)<>MATCH(A8,$A:$A,0)) -> 0 | F8: =IF(COUNTIF('Start Set'!A:A, A8) > 0, 1, 0) -> 0 | G8: =IF(COUNTIF('Iteration 1 - Forward'!A:A, A8) > 0, 1, 0) -> 0 | H8: =IF(COUNTIF('Iteration 1 - Backward'!A:A, A8) > 0, 1, 0) -> 0 | J8: 1
A9: Failure analysis in next-generation critical cellular communication infrastructures | B9: S Bi; X Yuan; S Hu; K Li; W Ni; E Hossain | C9: 2024 | D9: arXiv preprint arXiv | E9: =--(ROW(A9)<>MATCH(A9,$A:$A,0)) -> 0 | F9: =IF(COUNTIF('Start Set'!A:A, A9) > 0, 1, 0) -> 0 | G9: =IF(COUNTIF('Iteration 1 - Forward'!A:A, A9) > 0, 1, 0) -> 0 | H9: =IF(COUNTIF('Iteration 1 - Backward'!A:A, A9) > 0, 1, 0) -> 0 | J9: 1
A10: A Comprehensive Survey of 5G URLLC and Challenges in the 6G Era | B10: ME Haque, F Tariq, MRA Khandaker… | C10: 2025 | D10: arXiv preprint arXiv … | E10: =--(ROW(A10)<>MATCH(A10,$A:$A,0)) -> 0 | F10: =IF(COUNTIF('Start Set'!A:A, A10) > 0, 1, 0) -> 0 | G10: =IF(COUNTIF('Iteration 1 - Forward'!A:A, A10) > 0, 1, 0) -> 0 | H10: =IF(COUNTIF('Iteration 1 - Backward'!A:A, A10) > 0, 1, 0) -> 0 | J10: 1
A11: Performance analysis of UAV-assisted RF-UOWC systems | B11: T Devaja, M Petkovic, M Beko… | C11: 2024 | D11: arXiv preprint arXiv … | E11: =--(ROW(A11)<>MATCH(A11,$A:$A,0)) -> 0 | F11: =IF(COUNTIF('Start Set'!A:A, A11) > 0, 1, 0) -> 0 | G11: =IF(COUNTIF('Iteration 1 - Forward'!A:A, A11) > 0, 1, 0) -> 0 | H11: =IF(COUNTIF('Iteration 1 - Backward'!A:A, A11) > 0, 1, 0) -> 0 | J11: 1
A12: Communication Architecture for Autonomous Power-to-X Platforms: Enhancing Inspection and Operation With Legged Robots and 5G | B12: P Frank, F Dettinger, D Dittler, P Häbig, N Jazdi… | C12: 2025 | D12: arXiv preprint arXiv … | E12: =--(ROW(A12)<>MATCH(A12,$A:$A,0)) -> 0 | F12: =IF(COUNTIF('Start Set'!A:A, A12) > 0, 1, 0) -> 0 | G12: =IF(COUNTIF('Iteration 1 - Forward'!A:A, A12) > 0, 1, 0) -> 0 | H12: =IF(COUNTIF('Iteration 1 - Backward'!A:A, A12) > 0, 1, 0) -> 0 | J12: 1
A13: Energy, Scalability, Data and Security in Massive IoT: Current Landscape and Future Directions | B13: I Cheikh, S Roy, E Sabir, R Aouami | C13: 2025 | D13: arXiv preprint arXiv … | E13: =--(ROW(A13)<>MATCH(A13,$A:$A,0)) -> 0 | F13: =IF(COUNTIF('Start Set'!A:A, A13) > 0, 1, 0) -> 0 | G13: =IF(COUNTIF('Iteration 1 - Forward'!A:A, A13) > 0, 1, 0) -> 0 | H13: =IF(COUNTIF('Iteration 1 - Backward'!A:A, A13) > 0, 1, 0) -> 0 | J13: 1
A14: A Hierarchical Optimization Framework Using Deep Reinforcement Learning for Task-Driven Bandwidth Allocation in 5G Teleoperation | B14: N Golmohammadi, MM Rayguru, S Baidya | C14: 2025 | D14: arXiv preprint arXiv … | E14: =--(ROW(A14)<>MATCH(A14,$A:$A,0)) -> 0 | F14: =IF(COUNTIF('Start Set'!A:A, A14) > 0, 1, 0) -> 0 | G14: =IF(COUNTIF('Iteration 1 - Forward'!A:A, A14) > 0, 1, 0) -> 0 | H14: =IF(COUNTIF('Iteration 1 - Backward'!A:A, A14) > 0, 1, 0) -> 0 | J14: 1
A15: QoS-Aware Proportional Fairness Scheduling for Multi-Flow 5G UEs: A Smart Factory Perspective | B15: M Seliem, U Roedig, C Sreenan, D Pesch | C15: 2025 | D15: arXiv preprint arXiv … | E15: =--(ROW(A15)<>MATCH(A15,$A:$A,0)) -> 0 | F15: =IF(COUNTIF('Start Set'!A:A, A15) > 0, 1, 0) -> 0 | G15: =IF(COUNTIF('Iteration 1 - Forward'!A:A, A15) > 0, 1, 0) -> 0 | H15: =IF(COUNTIF('Iteration 1 - Backward'!A:A, A15) > 0, 1, 0) -> 0 | J15: 1
A16: On Enhancing Network Throughput using Reinforcement Learning in Sliced Testbeds | B16: DP Monteiro, LNFB Saar, LFR Moreira… | C16: 2024 | D16: arXiv preprint arXiv … | E16: =--(ROW(A16)<>MATCH(A16,$A:$A,0)) -> 0 | F16: =IF(COUNTIF('Start Set'!A:A, A16) > 0, 1, 0) -> 0 | G16: =IF(COUNTIF('Iteration 1 - Forward'!A:A, A16) > 0, 1, 0) -> 0 | H16: =IF(COUNTIF('Iteration 1 - Backward'!A:A, A16) > 0, 1, 0) -> 0 | J16: 1
A17: Ultra-reliable low-latency millimeter-wave communications with sliding window network coding | B17: E Dias, D Raposo, H Esfahanizadeh, A Cohen… | C17: 2022 | D17: arXiv preprint arXiv … | E17: =--(ROW(A17)<>MATCH(A17,$A:$A,0)) -> 0 | F17: =IF(COUNTIF('Start Set'!A:A, A17) > 0, 1, 0) -> 0 | G17: =IF(COUNTIF('Iteration 1 - Forward'!A:A, A17) > 0, 1, 0) -> 0 | H17: =IF(COUNTIF('Iteration 1 - Backward'!A:A, A17) > 0, 1, 0) -> 0 | J17: 1
A18: Admission Control with Reconfigurable Intelligent Surfaces for 6G Mobile Edge Computing | B18: Y Zhang, B Xiao, J Sahni, A Valera, W Li… | C18: 2025 | D18: arXiv preprint arXiv … | E18: =--(ROW(A18)<>MATCH(A18,$A:$A,0)) -> 0 | F18: =IF(COUNTIF('Start Set'!A:A, A18) > 0, 1, 0) -> 0 | G18: =IF(COUNTIF('Iteration 1 - Forward'!A:A, A18) > 0, 1, 0) -> 0 | H18: =IF(COUNTIF('Iteration 1 - Backward'!A:A, A18) > 0, 1, 0) -> 0 | J18: 1
... A25: Exploring Scientific Principles and Laws of Artificial Intelligence, World Model, and Artificial General Intelligence (AGI) in Future Intelligence Networking | B25: D Zhang; W Shi; X Jia | C25: 2025 | D25: Authorea Preprints (TechRxiv) | E25: =--(ROW(A25)<>MATCH(A25,$A:$A,0)) -> 0 | F25: =IF(COUNTIF('Start Set'!A:A, A25) > 0, 1, 0) -> 0 | G25: =IF(COUNTIF('Iteration 1 - Forward'!A:A, A25) > 0, 1, 0) -> 0 | H25: =IF(COUNTIF('Iteration 1 - Backward'!A:A, A25) > 0, 1, 0) -> 0 | J25: 1
A26: OFFLOADING DE APLICAÇÕES ESTRUTURADAS COMO DAGS PARA A BORDA DA REDE | B26: GFC de Queiroz | C26: 2024 | D26: cos.ufrj.br | E26: =--(ROW(A26)<>MATCH(A26,$A:$A,0)) -> 0 | F26: =IF(COUNTIF('Start Set'!A:A, A26) > 0, 1, 0) -> 0 | G26: =IF(COUNTIF('Iteration 1 - Forward'!A:A, A26) > 0, 1, 0) -> 0 | H26: =IF(COUNTIF('Iteration 1 - Backward'!A:A, A26) > 0, 1, 0) -> 0 | L26: 1
A27: Ultra-Reliable and Resilient Communication Service for Cyber-Physical Systems | B27: M Ganjalizadeh | C27: 2023 | D27: diva-portal.org | E27: =--(ROW(A27)<>MATCH(A27,$A:$A,0)) -> 0 | F27: =IF(COUNTIF('Start Set'!A:A, A27) > 0, 1, 0) -> 0 | G27: =IF(COUNTIF('Iteration 1 - Forward'!A:A, A27) > 0, 1, 0) -> 0 | H27: =IF(COUNTIF('Iteration 1 - Backward'!A:A, A27) > 0, 1, 0) -> 0 | J27: 1
A28: АНАЛИЗ ПОКАЗАТЕЛЕЙ ЭФФЕКТИВНОСТИ ПЕРЕДАЧИ ШИРОКОПОЛОСНОГО ТРАФИКА ПРИ ПРИОРИТЕТНЫХ СЕССИЯХ С НИЗКОЙ ЗАДЕРЖКОЙ В … | B28: КА Леонтьева; ЕД Макеева; ОД Лизюра | C28: 2023 | D28: elibrary.ru | E28: =--(ROW(A28)<>MATCH(A28,$A:$A,0)) -> 0 | F28: =IF(COUNTIF('Start Set'!A:A, A28) > 0, 1, 0) -> 0 | G28: =IF(COUNTIF('Iteration 1 - Forward'!A:A, A28) > 0, 1, 0) -> 0 | H28: =IF(COUNTIF('Iteration 1 - Backward'!A:A, A28) > 0, 1, 0) -> 0 | L28: 1
A29: Towards Accessible and Inclusive Remote Musical Interactions | B29: M Sacchetto | C29: 2025 | D29: PhD Thesis (depositolegale.it) | E29: =--(ROW(A29)<>MATCH(A29,$A:$A,0)) -> 0 | F29: =IF(COUNTIF('Start Set'!A:A, A29) > 0, 1, 0) -> 0 | G29: =IF(COUNTIF('Iteration 1 - Forward'!A:A, A29) > 0, 1, 0) -> 0 | H29: =IF(COUNTIF('Iteration 1 - Backward'!A:A, A29) > 0, 1, 0) -> 0 | J29: 1
A30: Sistema SCADA para mejorar el proceso de filtrado y extracción de agua en una empresa agroindustrial en Olmos | B30: CR Aguilar García; MC Maquén Perleche | C30: 2025 | D30: Repositorio UNPRG (Peru) | E30: =--(ROW(A30)<>MATCH(A30,$A:$A,0)) -> 0 | F30: =IF(COUNTIF('Start Set'!A:A, A30) > 0, 1, 0) -> 0 | G30: =IF(COUNTIF('Iteration 1 - Forward'!A:A, A30) > 0, 1, 0) -> 0 | H30: =IF(COUNTIF('Iteration 1 - Backward'!A:A, A30) > 0, 1, 0) -> 0 | L30: 1
A31: Caracterización y análisis de rendimiento del protocolo Zenoh para su aplicación a entornos IIoT | B31: M Barón Herrá | C31: 2024 | D31: repositorio.unican.es | E31: =--(ROW(A31)<>MATCH(A31,$A:$A,0)) -> 0 | F31: =IF(COUNTIF('Start Set'!A:A, A31) > 0, 1, 0) -> 0 | G31: =IF(COUNTIF('Iteration 1 - Forward'!A:A, A31) > 0, 1, 0) -> 0 | H31: =IF(COUNTIF('Iteration 1 - Backward'!A:A, A31) > 0, 1, 0) -> 0 | L31: 1
A32: Privatna 5G mreža zasnovana na programski definiranom radio uređaju | B32: T Karimović | C32: 2023 | D32: repozitorij.unios.hr | E32: =--(ROW(A32)<>MATCH(A32,$A:$A,0)) -> 0 | F32: =IF(COUNTIF('Start Set'!A:A, A32) > 0, 1, 0) -> 0 | G32: =IF(COUNTIF('Iteration 1 - Forward'!A:A, A32) > 0, 1, 0) -> 0 | H32: =IF(COUNTIF('Iteration 1 - Backward'!A:A, A32) > 0, 1, 0) -> 0 | L32: 1
A33: URLLC in Next-Generation Wireless Networks: Current Progress and Open Challenges | B33: A Saeed | C33: 2025 | D33: techrxiv.org | E33: =--(ROW(A33)<>MATCH(A33,$A:$A,0)) -> 0 | F33: =IF(COUNTIF('Start Set'!A:A, A33) > 0, 1, 0) -> 0 | G33: =IF(COUNTIF('Iteration 1 - Forward'!A:A, A33) > 0, 1, 0) -> 0 | H33: =IF(COUNTIF('Iteration 1 - Backward'!A:A, A33) > 0, 1, 0) -> 0 | J33: 1
A34: Task-oriented communication for edge intelligence enabled connected robotics systems | B34: Y Diao | C34: 2025 | D34: theses.gla.ac.uk | E34: =--(ROW(A34)<>MATCH(A34,$A:$A,0)) -> 0 | F34: =IF(COUNTIF('Start Set'!A:A, A34) > 0, 1, 0) -> 0 | G34: =IF(COUNTIF('Iteration 1 - Forward'!A:A, A34) > 0, 1, 0) -> 0 | H34: =IF(COUNTIF('Iteration 1 - Backward'!A:A, A34) > 0, 1, 0) -> 0 | J34: 1
A35: DISEÑO CONCEPTUAL DE UNA LÍNEA PILOTO DE INDUSTRIA 4.0 PARA LA CAPACITACIÓN Y LA INVESTIGACIÓN | B35: T Pérez Sosa; R Quiza Sardiñas; M Rivas Santana | C35: 2025 | D35: Universidad de Matanzas (rein.umcc.cu) | E35: =--(ROW(A35)<>MATCH(A35,$A:$A,0)) -> 0 | F35: =IF(COUNTIF('Start Set'!A:A, A35) > 0, 1, 0) -> 0 | G35: =IF(COUNTIF('Iteration 1 - Forward'!A:A, A35) > 0, 1, 0) -> 0 | H35: =IF(COUNTIF('Iteration 1 - Backward'!A:A, A35) > 0, 1, 0) -> 0 | L35: 1
A36: Contribution to the enhancement of IoT-based application development and optimization of underwater communications, by artificial intelligence, edge … | B36: JC Cepeda Pacheco | C36: 2024 | D36: Universitat Politècnica de Catalunya | E36: =--(ROW(A36)<>MATCH(A36,$A:$A,0)) -> 0 | F36: =IF(COUNTIF('Start Set'!A:A, A36) > 0, 1, 0) -> 0 | G36: =IF(COUNTIF('Iteration 1 - Forward'!A:A, A36) > 0, 1, 0) -> 0 | H36: =IF(COUNTIF('Iteration 1 - Backward'!A:A, A36) > 0, 1, 0) -> 0 | J36: 1
A37: Sicurezza e safety in ambienti industriali basati su IoT | B37: F Tommasin | D37: University of Padova (thesis.unipd.it) | E37: =--(ROW(A37)<>MATCH(A37,$A:$A,0)) -> 0 | F37: =IF(COUNTIF('Start Set'!A:A, A37) > 0, 1, 0) -> 0 | G37: =IF(COUNTIF('Iteration 1 - Forward'!A:A, A37) > 0, 1, 0) -> 0 | H37: =IF(COUNTIF('Iteration 1 - Backward'!A:A, A37) > 0, 1, 0) -> 0 | L37: 1
A38: 실외 디지털트윈을 활용하는 캠퍼스 특화망 구성 및 전송 성능 최적화 방안 | B38: 고제우; 이정윤; 노현석; 성원진 | C38: 2023 | D38: 한국통신학회 학술대회논문집 (dbpia.co.kr) | E38: =--(ROW(A38)<>MATCH(A38,$A:$A,0)) -> 0 | F38: =IF(COUNTIF('Start Set'!A:A, A38) > 0, 1, 0) -> 0 | G38: =IF(COUNTIF('Iteration 1 - Forward'!A:A, A38) > 0, 1, 0) -> 0 | H38: =IF(COUNTIF('Iteration 1 - Backward'!A:A, A38) > 0, 1, 0) -> 0 | L38: 1
A39: Enhancing Reliability and Energy Efficiency for IndustrialIoT Using IRSA-PSO | B39: WJ Ryu, JH Lee, JH Yu, DS Kim | C39: 2023 | D39: 한국통신학회논문지 | E39: =--(ROW(A39)<>MATCH(A39,$A:$A,0)) -> 0 | F39: =IF(COUNTIF('Start Set'!A:A, A39) > 0, 1, 0) -> 0 | G39: =IF(COUNTIF('Iteration 1 - Forward'!A:A, A39) > 0, 1, 0) -> 0 | H39: =IF(COUNTIF('Iteration 1 - Backward'!A:A, A39) > 0, 1, 0) -> 0 | L39: 1
A40: URLLC in Future Wireless Systems: Achievements, Gaps, and the Path Forward | B40: A Saeed | D40: academia.edu | E40: =--(ROW(A40)<>MATCH(A40,$A:$A,0)) -> 0 | F40: =IF(COUNTIF('Start Set'!A:A, A40) > 0, 1, 0) -> 0 | G40: =IF(COUNTIF('Iteration 1 - Forward'!A:A, A40) > 0, 1, 0) -> 0 | H40: =IF(COUNTIF('Iteration 1 - Backward'!A:A, A40) > 0, 1, 0) -> 0 | J40: 1
A41: Resource Allocation and Adaptive Channel Scheduling for 5G New Radio | B41: S Pandit, A Kumar | C41: 2024 | D41: ir.juit.ac.in | E41: =--(ROW(A41)<>MATCH(A41,$A:$A,0)) -> 0 | F41: =IF(COUNTIF('Start Set'!A:A, A41) > 0, 1, 0) -> 0 | G41: =IF(COUNTIF('Iteration 1 - Forward'!A:A, A41) > 0, 1, 0) -> 0 | H41: =IF(COUNTIF('Iteration 1 - Backward'!A:A, A41) > 0, 1, 0) -> 0 | J41: 1
A42: Iterative decoding of short low-density parity-check codes based on differential evolution | B42: M Shtompel, S Prykhodko | C42: 2024 | D42: lib.kart.edu.ua | E42: =--(ROW(A42)<>MATCH(A42,$A:$A,0)) -> 0 | F42: =IF(COUNTIF('Start Set'!A:A, A42) > 0, 1, 0) -> 0 | G42: =IF(COUNTIF('Iteration 1 - Forward'!A:A, A42) > 0, 1, 0) -> 0 | H42: =IF(COUNTIF('Iteration 1 - Backward'!A:A, A42) > 0, 1, 0) -> 0 | J42: 1
A43: Advancements in Ultra-Reliable Low-Latency Communication (URLLC) and Integrated Sensing and Communication (ISAC) in the 6G Era | B43: HA Jasim, SA Khudhair, NK Aljbur, W Fadhil | D43: magazine.iuc.edu.iq | E43: =--(ROW(A43)<>MATCH(A43,$A:$A,0)) -> 0 | F43: =IF(COUNTIF('Start Set'!A:A, A43) > 0, 1, 0) -> 0 | G43: =IF(COUNTIF('Iteration 1 - Forward'!A:A, A43) > 0, 1, 0) -> 0 | H43: =IF(COUNTIF('Iteration 1 - Backward'!A:A, A43) > 0, 1, 0) -> 0 | J43: 1
A44: Artificial Intelligence (AI)-enabled Smart Radio Environments for 6G Wireless Networks | B44: F Kavehmadavani | C44: 2024 | D44: orbilu.uni.lu | E44: =--(ROW(A44)<>MATCH(A44,$A:$A,0)) -> 0 | F44: =IF(COUNTIF('Start Set'!A:A, A44) > 0, 1, 0) -> 0 | G44: =IF(COUNTIF('Iteration 1 - Forward'!A:A, A44) > 0, 1, 0) -> 0 | H44: =IF(COUNTIF('Iteration 1 - Backward'!A:A, A44) > 0, 1, 0) -> 0 | J44: 1
A45: Analytical evaluation of the performance of a high-loaded 5G-IoT ecosystem functioning | B45: V Kovtun, O Kovtun, M Yukhimchuk | C45: 2025 | D45: ceur-ws.org | E45: =--(ROW(A45)<>MATCH(A45,$A:$A,0)) -> 0 | F45: =IF(COUNTIF('Start Set'!A:A, A45) > 0, 1, 0) -> 0 | G45: =IF(COUNTIF('Iteration 1 - Forward'!A:A, A45) > 0, 1, 0) -> 0 | H45: =IF(COUNTIF('Iteration 1 - Backward'!A:A, A45) > 0, 1, 0) -> 0 | J45: 1
A46: Orchestrating a Smart Agriculture System with Optimized Sensor Allocations and Heterogeneous Wireless Coverage | B46: MH Naeem; MA El-Khoreby; HM ELAttar | C46: 2025 | D46: Cureus (ResearchGate) | E46: =--(ROW(A46)<>MATCH(A46,$A:$A,0)) -> 0 | F46: =IF(COUNTIF('Start Set'!A:A, A46) > 0, 1, 0) -> 0 | G46: =IF(COUNTIF('Iteration 1 - Forward'!A:A, A46) > 0, 1, 0) -> 0 | H46: =IF(COUNTIF('Iteration 1 - Backward'!A:A, A46) > 0, 1, 0) -> 0 | J46: 1
...

Sheet Iteration 2 - Forward-Backward
A1: Title | B1: Authors | C1: Year | D1: Venue | E1: D | F1: DS | G1: DF | H1: DB | I1: DFF | J1: EC1 | K1: EC2 | L1: EC3 | M1: EC4 | N1: EC5 | O1: EC6 | P1: IC1
A2: Specification of Internet transmission control program | B2: V. Cerf, Y. Dalal, C. Sunshine | C2: 1974 | D2: RFC 675 (ETSI) | E2: =--(ROW(A2)<>MATCH(A2,$A:$A,0)) -> 0 | F2: =IF(COUNTIF('Start Set'!A:A, A2) > 0, 1, 0) -> 0 | G2: =IF(COUNTIF('Iteration 1 - Forward'!A:A, A2) > 0, 1, 0) -> 0 | H2: =IF(COUNTIF('Iteration 1 - Backward'!A:A, A2) > 0, 1, 0) -> 0 | I2: =IF(COUNTIF('Iteration 2 - Forward-Forward'!A:A, A2) > 0, 1, 0) -> 0 | J2: 1
A3: Long short-term memory | B3: S. Hochreiter, J. Schmidhuber | C3: 1997 | D3: Neural Comput. | E3: =--(ROW(A3)<>MATCH(A3,$A:$A,0)) -> 0 | F3: =IF(COUNTIF('Start Set'!A:A, A3) > 0, 1, 0) -> 0 | G3: =IF(COUNTIF('Iteration 1 - Forward'!A:A, A3) > 0, 1, 0) -> 0 | H3: =IF(COUNTIF('Iteration 1 - Backward'!A:A, A3) > 0, 1, 0) -> 0 | I3: =IF(COUNTIF('Iteration 2 - Forward-Forward'!A:A, A3) > 0, 1, 0) -> 0 | J3: 1
A4: The MOSIX multicomputer operating system for high performance cluster computing | B4: A. Barak, O. La’adan | C4: 1998 | D4: Future Gener. Comput. Syst. | E4: =--(ROW(A4)<>MATCH(A4,$A:$A,0)) -> 0 | F4: =IF(COUNTIF('Start Set'!A:A, A4) > 0, 1, 0) -> 0 | G4: =IF(COUNTIF('Iteration 1 - Forward'!A:A, A4) > 0, 1, 0) -> 0 | H4: =IF(COUNTIF('Iteration 1 - Backward'!A:A, A4) > 0, 1, 0) -> 0 | I4: =IF(COUNTIF('Iteration 2 - Forward-Forward'!A:A, A4) > 0, 1, 0) -> 0 | J4: 1
A5: The high-performance computing continuum | B5: S. Karin, S. Graham | C5: 1998 | D5: Commun. ACM | E5: =--(ROW(A5)<>MATCH(A5,$A:$A,0)) -> 0 | F5: =IF(COUNTIF('Start Set'!A:A, A5) > 0, 1, 0) -> 0 | G5: =IF(COUNTIF('Iteration 1 - Forward'!A:A, A5) > 0, 1, 0) -> 0 | H5: =IF(COUNTIF('Iteration 1 - Backward'!A:A, A5) > 0, 1, 0) -> 0 | I5: =IF(COUNTIF('Iteration 2 - Forward-Forward'!A:A, A5) > 0, 1, 0) -> 0 | J5: 1
A6: Performance evaluation of four field buses | B6: M. Rubio Benito, J. Fuertes, E. Kahoraho, N. P. Arzoz | C6: 1999 | D6: 7th IEEE International Conference on Emerging Technologies and Factory Automation (ETFA) | E6: =--(ROW(A6)<>MATCH(A6,$A:$A,0)) -> 0 | F6: =IF(COUNTIF('Start Set'!A:A, A6) > 0, 1, 0) -> 0 | G6: =IF(COUNTIF('Iteration 1 - Forward'!A:A, A6) > 0, 1, 0) -> 0 | H6: =IF(COUNTIF('Iteration 1 - Backward'!A:A, A6) > 0, 1, 0) -> 0 | I6: =IF(COUNTIF('Iteration 2 - Forward-Forward'!A:A, A6) > 0, 1, 0) -> 0 | J6: 1
A7: Co-operation and comparison of DiffServ and IntServ: Performance measurements | B7: J. Harju, P. Kivimaki | C7: 2000 | D7: 25th Conference on Local Computer Networks (LCN) | E7: =--(ROW(A7)<>MATCH(A7,$A:$A,0)) -> 0 | F7: =IF(COUNTIF('Start Set'!A:A, A7) > 0, 1, 0) -> 0 | G7: =IF(COUNTIF('Iteration 1 - Forward'!A:A, A7) > 0, 1, 0) -> 0 | H7: =IF(COUNTIF('Iteration 1 - Backward'!A:A, A7) > 0, 1, 0) -> 0 | I7: =IF(COUNTIF('Iteration 2 - Forward-Forward'!A:A, A7) > 0, 1, 0) -> 0 | J7: 1
A8: Beowulf Cluster Computing with Linux | B8: T.L. Sterling | C8: 2002 | D8: MIT Press | E8: =--(ROW(A8)<>MATCH(A8,$A:$A,0)) -> 0 | F8: =IF(COUNTIF('Start Set'!A:A, A8) > 0, 1, 0) -> 0 | G8: =IF(COUNTIF('Iteration 1 - Forward'!A:A, A8) > 0, 1, 0) -> 0 | H8: =IF(COUNTIF('Iteration 1 - Backward'!A:A, A8) > 0, 1, 0) -> 0 | I8: =IF(COUNTIF('Iteration 2 - Forward-Forward'!A:A, A8) > 0, 1, 0) -> 0 | J8: 1
A9: Ubiquitous computing | B9: K. Lyytinen, Y. Yoo | C9: 2002 | D9: Commun. ACM | E9: =--(ROW(A9)<>MATCH(A9,$A:$A,0)) -> 0 | F9: =IF(COUNTIF('Start Set'!A:A, A9) > 0, 1, 0) -> 0 | G9: =IF(COUNTIF('Iteration 1 - Forward'!A:A, A9) > 0, 1, 0) -> 0 | H9: =IF(COUNTIF('Iteration 1 - Backward'!A:A, A9) > 0, 1, 0) -> 0 | I9: =IF(COUNTIF('Iteration 2 - Forward-Forward'!A:A, A9) > 0, 1, 0) -> 0 | J9: 1
A10: Gridsim: A toolkit for the modeling and simulation of distributed resource management and scheduling for grid computing | B10: R. Buyya, M. Murshed | C10: 2002 | D10: Concurr. Comput.: Pract. Exp. | E10: =--(ROW(A10)<>MATCH(A10,$A:$A,0)) -> 0 | F10: =IF(COUNTIF('Start Set'!A:A, A10) > 0, 1, 0) -> 0 | G10: =IF(COUNTIF('Iteration 1 - Forward'!A:A, A10) > 0, 1, 0) -> 0 | H10: =IF(COUNTIF('Iteration 1 - Backward'!A:A, A10) > 0, 1, 0) -> 0 | I10: =IF(COUNTIF('Iteration 2 - Forward-Forward'!A:A, A10) > 0, 1, 0) -> 0 | J10: 1
A11: The fieldbus standards: History and structures | B11: M. Felser | C11: 2002 | D11: Technology Leadership Day (MICROSWISS Network) | E11: =--(ROW(A11)<>MATCH(A11,$A:$A,0)) -> 0 | F11: =IF(COUNTIF('Start Set'!A:A, A11) > 0, 1, 0) -> 0 | G11: =IF(COUNTIF('Iteration 1 - Forward'!A:A, A11) > 0, 1, 0) -> 0 | H11: =IF(COUNTIF('Iteration 1 - Backward'!A:A, A11) > 0, 1, 0) -> 0 | I11: =IF(COUNTIF('Iteration 2 - Forward-Forward'!A:A, A11) > 0, 1, 0) -> 0 | J11: 1
A12: Content delivery networks: status and trends | B12: A. Vakali, G. Pallis | C12: 2003 | D12: IEEE Internet Comput. | E12: =--(ROW(A12)<>MATCH(A12,$A:$A,0)) -> 0 | F12: =IF(COUNTIF('Start Set'!A:A, A12) > 0, 1, 0) -> 0 | G12: =IF(COUNTIF('Iteration 1 - Forward'!A:A, A12) > 0, 1, 0) -> 0 | H12: =IF(COUNTIF('Iteration 1 - Backward'!A:A, A12) > 0, 1, 0) -> 0 | I12: =IF(COUNTIF('Iteration 2 - Forward-Forward'!A:A, A12) > 0, 1, 0) -> 0 | J12: 1
A13: Autonomic computing: An overview | B13: M. Parashar, S. Hariri | C13: 2004 | D13: International Workshop on Unconventional Programming Paradigms | E13: =--(ROW(A13)<>MATCH(A13,$A:$A,0)) -> 0 | F13: =IF(COUNTIF('Start Set'!A:A, A13) > 0, 1, 0) -> 0 | G13: =IF(COUNTIF('Iteration 1 - Forward'!A:A, A13) > 0, 1, 0) -> 0 | H13: =IF(COUNTIF('Iteration 1 - Backward'!A:A, A13) > 0, 1, 0) -> 0 | I13: =IF(COUNTIF('Iteration 2 - Forward-Forward'!A:A, A13) > 0, 1, 0) -> 0 | J13: 1
... A50: Security and privacy challenges in Industrial Internet of Things | B50: A.-R. Sadeghi, C. Wachsmann, M. Waidner | C50: 2015 | D50: DAC: ACM/EDAC/IEEE Design Automation Conference | E50: =--(ROW(A50)<>MATCH(A50,$A:$A,0)) -> 0 | F50: =IF(COUNTIF('Start Set'!A:A, A50) > 0, 1, 0) -> 0 | G50: =IF(COUNTIF('Iteration 1 - Forward'!A:A, A50) > 0, 1, 0) -> 0 | H50: =IF(COUNTIF('Iteration 1 - Backward'!A:A, A50) > 0, 1, 0) -> 1 | I50: =IF(COUNTIF('Iteration 2 - Forward-Forward'!A:A, A50) > 0, 1, 0) -> 0 | J50: 1
A51: Energy consumption optimization in cloud data centers | B51: D. Kliazovich, P. Bouvry, F. Granelli, N.L. da Fonseca | C51: 2015 | D51: Cloud Serv. Netw. Manag. | E51: =--(ROW(A51)<>MATCH(A51,$A:$A,0)) -> 0 | F51: =IF(COUNTIF('Start Set'!A:A, A51) > 0, 1, 0) -> 0 | G51: =IF(COUNTIF('Iteration 1 - Forward'!A:A, A51) > 0, 1, 0) -> 0 | H51: =IF(COUNTIF('Iteration 1 - Backward'!A:A, A51) > 0, 1, 0) -> 0 | I51: =IF(COUNTIF('Iteration 2 - Forward-Forward'!A:A, A51) > 0, 1, 0) -> 0 | J51: 1 | K51: 0
A52: Faster R-CNN: Towards real-time object detection with region proposal networks | B52: S. Ren, K. He, R. Girshick, J. Sun | C52: 2015 | D52: Proc. Adv. Neural Inf. Process. Syst. | E52: =--(ROW(A52)<>MATCH(A52,$A:$A,0)) -> 0 | F52: =IF(COUNTIF('Start Set'!A:A, A52) > 0, 1, 0) -> 0 | G52: =IF(COUNTIF('Iteration 1 - Forward'!A:A, A52) > 0, 1, 0) -> 0 | H52: =IF(COUNTIF('Iteration 1 - Backward'!A:A, A52) > 0, 1, 0) -> 0 | I52: =IF(COUNTIF('Iteration 2 - Forward-Forward'!A:A, A52) > 0, 1, 0) -> 0 | J52: 1 | K52: 0
A53: PISA: Protocol independent switch architecture | B53: N. McKeown | C53: 2015 | D53: P4 Workshop | E53: =--(ROW(A53)<>MATCH(A53,$A:$A,0)) -> 0 | F53: =IF(COUNTIF('Start Set'!A:A, A53) > 0, 1, 0) -> 0 | G53: =IF(COUNTIF('Iteration 1 - Forward'!A:A, A53) > 0, 1, 0) -> 0 | H53: =IF(COUNTIF('Iteration 1 - Backward'!A:A, A53) > 0, 1, 0) -> 0 | I53: =IF(COUNTIF('Iteration 2 - Forward-Forward'!A:A, A53) > 0, 1, 0) -> 0 | J53: 1 | K53: 0
A54: An industrial big data pipeline for data-driven analytics maintenance applications in large-scale smart manufacturing facilities | B54: P. O’Donovan, K. Leahy, K. Bruton, D. O’Sullivan | C54: 2015 | D54: Journal of Big Data | E54: =--(ROW(A54)<>MATCH(A54,$A:$A,0)) -> 0 | F54: =IF(COUNTIF('Start Set'!A:A, A54) > 0, 1, 0) -> 0 | G54: =IF(COUNTIF('Iteration 1 - Forward'!A:A, A54) > 0, 1, 0) -> 0 | H54: =IF(COUNTIF('Iteration 1 - Backward'!A:A, A54) > 0, 1, 0) -> 0 | I54: =IF(COUNTIF('Iteration 2 - Forward-Forward'!A:A, A54) > 0, 1, 0) -> 0 | J54: 1 | K54: 0
A55: On the ergodic capacity of MIMO NOMA systems | B55: Q. Sun, S. Han, C.-L. I, Z. Pan | C55: 2015 | D55: IEEE Wireless Communications Letters | E55: =--(ROW(A55)<>MATCH(A55,$A:$A,0)) -> 0 | F55: =IF(COUNTIF('Start Set'!A:A, A55) > 0, 1, 0) -> 0 | G55: =IF(COUNTIF('Iteration 1 - Forward'!A:A, A55) > 0, 1, 0) -> 0 | H55: =IF(COUNTIF('Iteration 1 - Backward'!A:A, A55) > 0, 1, 0) -> 0 | I55: =IF(COUNTIF('Iteration 2 - Forward-Forward'!A:A, A55) > 0, 1, 0) -> 0 | J55: 1 | K55: 0
A56: CometCloud: Enabling software-defined federations for end-to-end application workflows | B56: J. Diaz-Montes, M. AbdelBaky, M. Zou, M. Parashar | C56: 2015 | D56: IEEE Internet Comput. | E56: =--(ROW(A56)<>MATCH(A56,$A:$A,0)) -> 0 | F56: =IF(COUNTIF('Start Set'!A:A, A56) > 0, 1, 0) -> 0 | G56: =IF(COUNTIF('Iteration 1 - Forward'!A:A, A56) > 0, 1, 0) -> 0 | H56: =IF(COUNTIF('Iteration 1 - Backward'!A:A, A56) > 0, 1, 0) -> 0 | I56: =IF(COUNTIF('Iteration 2 - Forward-Forward'!A:A, A56) > 0, 1, 0) -> 0 | J56: 1 | K56: 0
